{
    "results": [
        {
            "task_id": "0",
            "success": true,
            "answer": "234",
            "token_usage": 10838,
            "num_times_pruned": 0
        },
        {
            "task_id": "1",
            "success": true,
            "answer": "615",
            "token_usage": 29326,
            "num_times_pruned": 0
        },
        {
            "task_id": "2",
            "success": true,
            "answer": "4",
            "token_usage": 7120,
            "num_times_pruned": 0
        },
        {
            "task_id": "3",
            "success": true,
            "answer": "11",
            "token_usage": 3985,
            "num_times_pruned": 0
        },
        {
            "task_id": "4",
            "success": true,
            "answer": "70",
            "token_usage": 18795,
            "num_times_pruned": 0
        },
        {
            "task_id": "5",
            "success": false,
            "answer": "Error occurred: APITimeoutError: Request timed out.\nTraceback:\nTraceback (most recent call last):\n  File \"/work/rleap1/leon.hamm/bachelor-thesis-dev/novelty_tot/.venv/lib/python3.10/site-packages/httpx/_transports/default.py\", line 101, in map_httpcore_exceptions\n    yield\n  File \"/work/rleap1/leon.hamm/bachelor-thesis-dev/novelty_tot/.venv/lib/python3.10/site-packages/httpx/_transports/default.py\", line 394, in handle_async_request\n    resp = await self._pool.handle_async_request(req)\n  File \"/work/rleap1/leon.hamm/bachelor-thesis-dev/novelty_tot/.venv/lib/python3.10/site-packages/httpcore/_async/connection_pool.py\", line 256, in handle_async_request\n    raise exc from None\n  File \"/work/rleap1/leon.hamm/bachelor-thesis-dev/novelty_tot/.venv/lib/python3.10/site-packages/httpcore/_async/connection_pool.py\", line 236, in handle_async_request\n    response = await connection.handle_async_request(\n  File \"/work/rleap1/leon.hamm/bachelor-thesis-dev/novelty_tot/.venv/lib/python3.10/site-packages/httpcore/_async/connection.py\", line 103, in handle_async_request\n    return await self._connection.handle_async_request(request)\n  File \"/work/rleap1/leon.hamm/bachelor-thesis-dev/novelty_tot/.venv/lib/python3.10/site-packages/httpcore/_async/http11.py\", line 136, in handle_async_request\n    raise exc\n  File \"/work/rleap1/leon.hamm/bachelor-thesis-dev/novelty_tot/.venv/lib/python3.10/site-packages/httpcore/_async/http11.py\", line 106, in handle_async_request\n    ) = await self._receive_response_headers(**kwargs)\n  File \"/work/rleap1/leon.hamm/bachelor-thesis-dev/novelty_tot/.venv/lib/python3.10/site-packages/httpcore/_async/http11.py\", line 177, in _receive_response_headers\n    event = await self._receive_event(timeout=timeout)\n  File \"/work/rleap1/leon.hamm/bachelor-thesis-dev/novelty_tot/.venv/lib/python3.10/site-packages/httpcore/_async/http11.py\", line 217, in _receive_event\n    data = await self._network_stream.read(\n  File \"/work/rleap1/leon.hamm/bachelor-thesis-dev/novelty_tot/.venv/lib/python3.10/site-packages/httpcore/_backends/anyio.py\", line 32, in read\n    with map_exceptions(exc_map):\n  File \"/usr/lib/python3.10/contextlib.py\", line 153, in __exit__\n    self.gen.throw(typ, value, traceback)\n  File \"/work/rleap1/leon.hamm/bachelor-thesis-dev/novelty_tot/.venv/lib/python3.10/site-packages/httpcore/_exceptions.py\", line 14, in map_exceptions\n    raise to_exc(exc) from exc\nhttpcore.ReadTimeout\n\nThe above exception was the direct cause of the following exception:\n\nTraceback (most recent call last):\n  File \"/work/rleap1/leon.hamm/bachelor-thesis-dev/novelty_tot/.venv/lib/python3.10/site-packages/openai/_base_client.py\", line 1526, in request\n    response = await self._client.send(\n  File \"/work/rleap1/leon.hamm/bachelor-thesis-dev/novelty_tot/.venv/lib/python3.10/site-packages/httpx/_client.py\", line 1629, in send\n    response = await self._send_handling_auth(\n  File \"/work/rleap1/leon.hamm/bachelor-thesis-dev/novelty_tot/.venv/lib/python3.10/site-packages/httpx/_client.py\", line 1657, in _send_handling_auth\n    response = await self._send_handling_redirects(\n  File \"/work/rleap1/leon.hamm/bachelor-thesis-dev/novelty_tot/.venv/lib/python3.10/site-packages/httpx/_client.py\", line 1694, in _send_handling_redirects\n    response = await self._send_single_request(request)\n  File \"/work/rleap1/leon.hamm/bachelor-thesis-dev/novelty_tot/.venv/lib/python3.10/site-packages/httpx/_client.py\", line 1730, in _send_single_request\n    response = await transport.handle_async_request(request)\n  File \"/work/rleap1/leon.hamm/bachelor-thesis-dev/novelty_tot/.venv/lib/python3.10/site-packages/httpx/_transports/default.py\", line 393, in handle_async_request\n    with map_httpcore_exceptions():\n  File \"/usr/lib/python3.10/contextlib.py\", line 153, in __exit__\n    self.gen.throw(typ, value, traceback)\n  File \"/work/rleap1/leon.hamm/bachelor-thesis-dev/novelty_tot/.venv/lib/python3.10/site-packages/httpx/_transports/default.py\", line 118, in map_httpcore_exceptions\n    raise mapped_exc(message) from exc\nhttpx.ReadTimeout\n\nThe above exception was the direct cause of the following exception:\n\nTraceback (most recent call last):\n  File \"/work/rleap1/leon.hamm/bachelor-thesis-dev/novelty_tot/tot_tester.py\", line 504, in run_math_task_with_error_handling\n    answer = await tot.run(query, parallel=parallel, breadth_first=breadth_first, problem_width=problem_width)\n  File \"/work/rleap1/leon.hamm/bachelor-thesis-dev/novelty_tot/tot.py\", line 233, in run\n    await self._expand_depth_first(self.init_state, self.max_depth, parallel=parallel)\n  File \"/work/rleap1/leon.hamm/bachelor-thesis-dev/novelty_tot/tot.py\", line 305, in _expand_depth_first\n    await self._expand_node(state, depth=depth, parallel=parallel)\n  File \"/work/rleap1/leon.hamm/bachelor-thesis-dev/novelty_tot/tot.py\", line 279, in _expand_node\n    results = await asyncio.gather(*scheduled)\n  File \"/work/rleap1/leon.hamm/bachelor-thesis-dev/novelty_tot/tot.py\", line 265, in process_branch\n    succ = await self._generate_successor(node)\n  File \"/work/rleap1/leon.hamm/bachelor-thesis-dev/novelty_tot/tot.py\", line 426, in _generate_successor\n    response = await self.query(complete_prompt)\n  File \"/work/rleap1/leon.hamm/bachelor-thesis-dev/novelty_tot/tot.py\", line 193, in query\n    response = await self.llm_engine.query(query)\n  File \"/work/rleap1/leon.hamm/bachelor-thesis-dev/novelty_tot/llm_engine.py\", line 203, in query\n    response = await client.aquery(\n  File \"/work/rleap1/leon.hamm/bachelor-thesis-dev/novelty_tot/llm_engine.py\", line 88, in aquery\n    response = await self.chat.completions.create(\n  File \"/work/rleap1/leon.hamm/bachelor-thesis-dev/novelty_tot/.venv/lib/python3.10/site-packages/openai/resources/chat/completions/completions.py\", line 2454, in create\n    return await self._post(\n  File \"/work/rleap1/leon.hamm/bachelor-thesis-dev/novelty_tot/.venv/lib/python3.10/site-packages/openai/_base_client.py\", line 1791, in post\n    return await self.request(cast_to, opts, stream=stream, stream_cls=stream_cls)\n  File \"/work/rleap1/leon.hamm/bachelor-thesis-dev/novelty_tot/.venv/lib/python3.10/site-packages/openai/_base_client.py\", line 1544, in request\n    raise APITimeoutError(request=request) from err\nopenai.APITimeoutError: Request timed out.\n",
            "token_usage": 0,
            "num_times_pruned": 0
        },
        {
            "task_id": "6",
            "success": false,
            "answer": "Error occurred: APITimeoutError: Request timed out.\nTraceback:\nTraceback (most recent call last):\n  File \"/work/rleap1/leon.hamm/bachelor-thesis-dev/novelty_tot/.venv/lib/python3.10/site-packages/httpx/_transports/default.py\", line 101, in map_httpcore_exceptions\n    yield\n  File \"/work/rleap1/leon.hamm/bachelor-thesis-dev/novelty_tot/.venv/lib/python3.10/site-packages/httpx/_transports/default.py\", line 394, in handle_async_request\n    resp = await self._pool.handle_async_request(req)\n  File \"/work/rleap1/leon.hamm/bachelor-thesis-dev/novelty_tot/.venv/lib/python3.10/site-packages/httpcore/_async/connection_pool.py\", line 256, in handle_async_request\n    raise exc from None\n  File \"/work/rleap1/leon.hamm/bachelor-thesis-dev/novelty_tot/.venv/lib/python3.10/site-packages/httpcore/_async/connection_pool.py\", line 236, in handle_async_request\n    response = await connection.handle_async_request(\n  File \"/work/rleap1/leon.hamm/bachelor-thesis-dev/novelty_tot/.venv/lib/python3.10/site-packages/httpcore/_async/connection.py\", line 103, in handle_async_request\n    return await self._connection.handle_async_request(request)\n  File \"/work/rleap1/leon.hamm/bachelor-thesis-dev/novelty_tot/.venv/lib/python3.10/site-packages/httpcore/_async/http11.py\", line 136, in handle_async_request\n    raise exc\n  File \"/work/rleap1/leon.hamm/bachelor-thesis-dev/novelty_tot/.venv/lib/python3.10/site-packages/httpcore/_async/http11.py\", line 106, in handle_async_request\n    ) = await self._receive_response_headers(**kwargs)\n  File \"/work/rleap1/leon.hamm/bachelor-thesis-dev/novelty_tot/.venv/lib/python3.10/site-packages/httpcore/_async/http11.py\", line 177, in _receive_response_headers\n    event = await self._receive_event(timeout=timeout)\n  File \"/work/rleap1/leon.hamm/bachelor-thesis-dev/novelty_tot/.venv/lib/python3.10/site-packages/httpcore/_async/http11.py\", line 217, in _receive_event\n    data = await self._network_stream.read(\n  File \"/work/rleap1/leon.hamm/bachelor-thesis-dev/novelty_tot/.venv/lib/python3.10/site-packages/httpcore/_backends/anyio.py\", line 32, in read\n    with map_exceptions(exc_map):\n  File \"/usr/lib/python3.10/contextlib.py\", line 153, in __exit__\n    self.gen.throw(typ, value, traceback)\n  File \"/work/rleap1/leon.hamm/bachelor-thesis-dev/novelty_tot/.venv/lib/python3.10/site-packages/httpcore/_exceptions.py\", line 14, in map_exceptions\n    raise to_exc(exc) from exc\nhttpcore.ReadTimeout\n\nThe above exception was the direct cause of the following exception:\n\nTraceback (most recent call last):\n  File \"/work/rleap1/leon.hamm/bachelor-thesis-dev/novelty_tot/.venv/lib/python3.10/site-packages/openai/_base_client.py\", line 1526, in request\n    response = await self._client.send(\n  File \"/work/rleap1/leon.hamm/bachelor-thesis-dev/novelty_tot/.venv/lib/python3.10/site-packages/httpx/_client.py\", line 1629, in send\n    response = await self._send_handling_auth(\n  File \"/work/rleap1/leon.hamm/bachelor-thesis-dev/novelty_tot/.venv/lib/python3.10/site-packages/httpx/_client.py\", line 1657, in _send_handling_auth\n    response = await self._send_handling_redirects(\n  File \"/work/rleap1/leon.hamm/bachelor-thesis-dev/novelty_tot/.venv/lib/python3.10/site-packages/httpx/_client.py\", line 1694, in _send_handling_redirects\n    response = await self._send_single_request(request)\n  File \"/work/rleap1/leon.hamm/bachelor-thesis-dev/novelty_tot/.venv/lib/python3.10/site-packages/httpx/_client.py\", line 1730, in _send_single_request\n    response = await transport.handle_async_request(request)\n  File \"/work/rleap1/leon.hamm/bachelor-thesis-dev/novelty_tot/.venv/lib/python3.10/site-packages/httpx/_transports/default.py\", line 393, in handle_async_request\n    with map_httpcore_exceptions():\n  File \"/usr/lib/python3.10/contextlib.py\", line 153, in __exit__\n    self.gen.throw(typ, value, traceback)\n  File \"/work/rleap1/leon.hamm/bachelor-thesis-dev/novelty_tot/.venv/lib/python3.10/site-packages/httpx/_transports/default.py\", line 118, in map_httpcore_exceptions\n    raise mapped_exc(message) from exc\nhttpx.ReadTimeout\n\nThe above exception was the direct cause of the following exception:\n\nTraceback (most recent call last):\n  File \"/work/rleap1/leon.hamm/bachelor-thesis-dev/novelty_tot/tot_tester.py\", line 504, in run_math_task_with_error_handling\n    answer = await tot.run(query, parallel=parallel, breadth_first=breadth_first, problem_width=problem_width)\n  File \"/work/rleap1/leon.hamm/bachelor-thesis-dev/novelty_tot/tot.py\", line 233, in run\n    await self._expand_depth_first(self.init_state, self.max_depth, parallel=parallel)\n  File \"/work/rleap1/leon.hamm/bachelor-thesis-dev/novelty_tot/tot.py\", line 305, in _expand_depth_first\n    await self._expand_node(state, depth=depth, parallel=parallel)\n  File \"/work/rleap1/leon.hamm/bachelor-thesis-dev/novelty_tot/tot.py\", line 279, in _expand_node\n    results = await asyncio.gather(*scheduled)\n  File \"/work/rleap1/leon.hamm/bachelor-thesis-dev/novelty_tot/tot.py\", line 265, in process_branch\n    succ = await self._generate_successor(node)\n  File \"/work/rleap1/leon.hamm/bachelor-thesis-dev/novelty_tot/tot.py\", line 426, in _generate_successor\n    response = await self.query(complete_prompt)\n  File \"/work/rleap1/leon.hamm/bachelor-thesis-dev/novelty_tot/tot.py\", line 193, in query\n    response = await self.llm_engine.query(query)\n  File \"/work/rleap1/leon.hamm/bachelor-thesis-dev/novelty_tot/llm_engine.py\", line 203, in query\n    response = await client.aquery(\n  File \"/work/rleap1/leon.hamm/bachelor-thesis-dev/novelty_tot/llm_engine.py\", line 88, in aquery\n    response = await self.chat.completions.create(\n  File \"/work/rleap1/leon.hamm/bachelor-thesis-dev/novelty_tot/.venv/lib/python3.10/site-packages/openai/resources/chat/completions/completions.py\", line 2454, in create\n    return await self._post(\n  File \"/work/rleap1/leon.hamm/bachelor-thesis-dev/novelty_tot/.venv/lib/python3.10/site-packages/openai/_base_client.py\", line 1791, in post\n    return await self.request(cast_to, opts, stream=stream, stream_cls=stream_cls)\n  File \"/work/rleap1/leon.hamm/bachelor-thesis-dev/novelty_tot/.venv/lib/python3.10/site-packages/openai/_base_client.py\", line 1544, in request\n    raise APITimeoutError(request=request) from err\nopenai.APITimeoutError: Request timed out.\n",
            "token_usage": 0,
            "num_times_pruned": 0
        },
        {
            "task_id": "7",
            "success": true,
            "answer": "689",
            "token_usage": 21999,
            "num_times_pruned": 0
        },
        {
            "task_id": "8",
            "success": true,
            "answer": "The probability is $\\frac{7}{16}$.",
            "token_usage": 18889,
            "num_times_pruned": 0
        },
        {
            "task_id": "9",
            "success": true,
            "answer": "$\\left(\\frac{1}{2}, \\frac{\\sqrt{7}}{2}\\right)$",
            "token_usage": 10234,
            "num_times_pruned": 0
        },
        {
            "task_id": "10",
            "success": true,
            "answer": "$\\frac{16\\sqrt{3}}{9}$",
            "token_usage": 8609,
            "num_times_pruned": 0
        },
        {
            "task_id": "11",
            "success": true,
            "answer": "13",
            "token_usage": 6485,
            "num_times_pruned": 0
        },
        {
            "task_id": "12",
            "success": true,
            "answer": "$\\frac{1}{2}$",
            "token_usage": 9167,
            "num_times_pruned": 0
        },
        {
            "task_id": "13",
            "success": true,
            "answer": "8.24",
            "token_usage": 75771,
            "num_times_pruned": 0
        },
        {
            "task_id": "14",
            "success": true,
            "answer": "-1",
            "token_usage": 2724,
            "num_times_pruned": 0
        },
        {
            "task_id": "15",
            "success": false,
            "answer": "Error occurred: APITimeoutError: Request timed out.\nTraceback:\nTraceback (most recent call last):\n  File \"/work/rleap1/leon.hamm/bachelor-thesis-dev/novelty_tot/.venv/lib/python3.10/site-packages/httpx/_transports/default.py\", line 101, in map_httpcore_exceptions\n    yield\n  File \"/work/rleap1/leon.hamm/bachelor-thesis-dev/novelty_tot/.venv/lib/python3.10/site-packages/httpx/_transports/default.py\", line 394, in handle_async_request\n    resp = await self._pool.handle_async_request(req)\n  File \"/work/rleap1/leon.hamm/bachelor-thesis-dev/novelty_tot/.venv/lib/python3.10/site-packages/httpcore/_async/connection_pool.py\", line 256, in handle_async_request\n    raise exc from None\n  File \"/work/rleap1/leon.hamm/bachelor-thesis-dev/novelty_tot/.venv/lib/python3.10/site-packages/httpcore/_async/connection_pool.py\", line 236, in handle_async_request\n    response = await connection.handle_async_request(\n  File \"/work/rleap1/leon.hamm/bachelor-thesis-dev/novelty_tot/.venv/lib/python3.10/site-packages/httpcore/_async/connection.py\", line 103, in handle_async_request\n    return await self._connection.handle_async_request(request)\n  File \"/work/rleap1/leon.hamm/bachelor-thesis-dev/novelty_tot/.venv/lib/python3.10/site-packages/httpcore/_async/http11.py\", line 136, in handle_async_request\n    raise exc\n  File \"/work/rleap1/leon.hamm/bachelor-thesis-dev/novelty_tot/.venv/lib/python3.10/site-packages/httpcore/_async/http11.py\", line 106, in handle_async_request\n    ) = await self._receive_response_headers(**kwargs)\n  File \"/work/rleap1/leon.hamm/bachelor-thesis-dev/novelty_tot/.venv/lib/python3.10/site-packages/httpcore/_async/http11.py\", line 177, in _receive_response_headers\n    event = await self._receive_event(timeout=timeout)\n  File \"/work/rleap1/leon.hamm/bachelor-thesis-dev/novelty_tot/.venv/lib/python3.10/site-packages/httpcore/_async/http11.py\", line 217, in _receive_event\n    data = await self._network_stream.read(\n  File \"/work/rleap1/leon.hamm/bachelor-thesis-dev/novelty_tot/.venv/lib/python3.10/site-packages/httpcore/_backends/anyio.py\", line 32, in read\n    with map_exceptions(exc_map):\n  File \"/usr/lib/python3.10/contextlib.py\", line 153, in __exit__\n    self.gen.throw(typ, value, traceback)\n  File \"/work/rleap1/leon.hamm/bachelor-thesis-dev/novelty_tot/.venv/lib/python3.10/site-packages/httpcore/_exceptions.py\", line 14, in map_exceptions\n    raise to_exc(exc) from exc\nhttpcore.ReadTimeout\n\nThe above exception was the direct cause of the following exception:\n\nTraceback (most recent call last):\n  File \"/work/rleap1/leon.hamm/bachelor-thesis-dev/novelty_tot/.venv/lib/python3.10/site-packages/openai/_base_client.py\", line 1526, in request\n    response = await self._client.send(\n  File \"/work/rleap1/leon.hamm/bachelor-thesis-dev/novelty_tot/.venv/lib/python3.10/site-packages/httpx/_client.py\", line 1629, in send\n    response = await self._send_handling_auth(\n  File \"/work/rleap1/leon.hamm/bachelor-thesis-dev/novelty_tot/.venv/lib/python3.10/site-packages/httpx/_client.py\", line 1657, in _send_handling_auth\n    response = await self._send_handling_redirects(\n  File \"/work/rleap1/leon.hamm/bachelor-thesis-dev/novelty_tot/.venv/lib/python3.10/site-packages/httpx/_client.py\", line 1694, in _send_handling_redirects\n    response = await self._send_single_request(request)\n  File \"/work/rleap1/leon.hamm/bachelor-thesis-dev/novelty_tot/.venv/lib/python3.10/site-packages/httpx/_client.py\", line 1730, in _send_single_request\n    response = await transport.handle_async_request(request)\n  File \"/work/rleap1/leon.hamm/bachelor-thesis-dev/novelty_tot/.venv/lib/python3.10/site-packages/httpx/_transports/default.py\", line 393, in handle_async_request\n    with map_httpcore_exceptions():\n  File \"/usr/lib/python3.10/contextlib.py\", line 153, in __exit__\n    self.gen.throw(typ, value, traceback)\n  File \"/work/rleap1/leon.hamm/bachelor-thesis-dev/novelty_tot/.venv/lib/python3.10/site-packages/httpx/_transports/default.py\", line 118, in map_httpcore_exceptions\n    raise mapped_exc(message) from exc\nhttpx.ReadTimeout\n\nThe above exception was the direct cause of the following exception:\n\nTraceback (most recent call last):\n  File \"/work/rleap1/leon.hamm/bachelor-thesis-dev/novelty_tot/tot_tester.py\", line 504, in run_math_task_with_error_handling\n    answer = await tot.run(query, parallel=parallel, breadth_first=breadth_first, problem_width=problem_width)\n  File \"/work/rleap1/leon.hamm/bachelor-thesis-dev/novelty_tot/tot.py\", line 233, in run\n    await self._expand_depth_first(self.init_state, self.max_depth, parallel=parallel)\n  File \"/work/rleap1/leon.hamm/bachelor-thesis-dev/novelty_tot/tot.py\", line 305, in _expand_depth_first\n    await self._expand_node(state, depth=depth, parallel=parallel)\n  File \"/work/rleap1/leon.hamm/bachelor-thesis-dev/novelty_tot/tot.py\", line 279, in _expand_node\n    results = await asyncio.gather(*scheduled)\n  File \"/work/rleap1/leon.hamm/bachelor-thesis-dev/novelty_tot/tot.py\", line 265, in process_branch\n    succ = await self._generate_successor(node)\n  File \"/work/rleap1/leon.hamm/bachelor-thesis-dev/novelty_tot/tot.py\", line 426, in _generate_successor\n    response = await self.query(complete_prompt)\n  File \"/work/rleap1/leon.hamm/bachelor-thesis-dev/novelty_tot/tot.py\", line 193, in query\n    response = await self.llm_engine.query(query)\n  File \"/work/rleap1/leon.hamm/bachelor-thesis-dev/novelty_tot/llm_engine.py\", line 203, in query\n    response = await client.aquery(\n  File \"/work/rleap1/leon.hamm/bachelor-thesis-dev/novelty_tot/llm_engine.py\", line 88, in aquery\n    response = await self.chat.completions.create(\n  File \"/work/rleap1/leon.hamm/bachelor-thesis-dev/novelty_tot/.venv/lib/python3.10/site-packages/openai/resources/chat/completions/completions.py\", line 2454, in create\n    return await self._post(\n  File \"/work/rleap1/leon.hamm/bachelor-thesis-dev/novelty_tot/.venv/lib/python3.10/site-packages/openai/_base_client.py\", line 1791, in post\n    return await self.request(cast_to, opts, stream=stream, stream_cls=stream_cls)\n  File \"/work/rleap1/leon.hamm/bachelor-thesis-dev/novelty_tot/.venv/lib/python3.10/site-packages/openai/_base_client.py\", line 1544, in request\n    raise APITimeoutError(request=request) from err\nopenai.APITimeoutError: Request timed out.\n",
            "token_usage": 0,
            "num_times_pruned": 0
        },
        {
            "task_id": "16",
            "success": true,
            "answer": "$\\boxed{\\dfrac{650}{51}}$",
            "token_usage": 9760,
            "num_times_pruned": 0
        },
        {
            "task_id": "17",
            "success": true,
            "answer": "$\\cos \\theta = \\frac{19}{21}$",
            "token_usage": 6431,
            "num_times_pruned": 0
        },
        {
            "task_id": "18",
            "success": true,
            "answer": "\\boxed{-i}",
            "token_usage": 8905,
            "num_times_pruned": 0
        },
        {
            "task_id": "19",
            "success": false,
            "answer": "Error occurred: APITimeoutError: Request timed out.\nTraceback:\nTraceback (most recent call last):\n  File \"/work/rleap1/leon.hamm/bachelor-thesis-dev/novelty_tot/.venv/lib/python3.10/site-packages/httpx/_transports/default.py\", line 101, in map_httpcore_exceptions\n    yield\n  File \"/work/rleap1/leon.hamm/bachelor-thesis-dev/novelty_tot/.venv/lib/python3.10/site-packages/httpx/_transports/default.py\", line 394, in handle_async_request\n    resp = await self._pool.handle_async_request(req)\n  File \"/work/rleap1/leon.hamm/bachelor-thesis-dev/novelty_tot/.venv/lib/python3.10/site-packages/httpcore/_async/connection_pool.py\", line 256, in handle_async_request\n    raise exc from None\n  File \"/work/rleap1/leon.hamm/bachelor-thesis-dev/novelty_tot/.venv/lib/python3.10/site-packages/httpcore/_async/connection_pool.py\", line 236, in handle_async_request\n    response = await connection.handle_async_request(\n  File \"/work/rleap1/leon.hamm/bachelor-thesis-dev/novelty_tot/.venv/lib/python3.10/site-packages/httpcore/_async/connection.py\", line 103, in handle_async_request\n    return await self._connection.handle_async_request(request)\n  File \"/work/rleap1/leon.hamm/bachelor-thesis-dev/novelty_tot/.venv/lib/python3.10/site-packages/httpcore/_async/http11.py\", line 136, in handle_async_request\n    raise exc\n  File \"/work/rleap1/leon.hamm/bachelor-thesis-dev/novelty_tot/.venv/lib/python3.10/site-packages/httpcore/_async/http11.py\", line 106, in handle_async_request\n    ) = await self._receive_response_headers(**kwargs)\n  File \"/work/rleap1/leon.hamm/bachelor-thesis-dev/novelty_tot/.venv/lib/python3.10/site-packages/httpcore/_async/http11.py\", line 177, in _receive_response_headers\n    event = await self._receive_event(timeout=timeout)\n  File \"/work/rleap1/leon.hamm/bachelor-thesis-dev/novelty_tot/.venv/lib/python3.10/site-packages/httpcore/_async/http11.py\", line 217, in _receive_event\n    data = await self._network_stream.read(\n  File \"/work/rleap1/leon.hamm/bachelor-thesis-dev/novelty_tot/.venv/lib/python3.10/site-packages/httpcore/_backends/anyio.py\", line 32, in read\n    with map_exceptions(exc_map):\n  File \"/usr/lib/python3.10/contextlib.py\", line 153, in __exit__\n    self.gen.throw(typ, value, traceback)\n  File \"/work/rleap1/leon.hamm/bachelor-thesis-dev/novelty_tot/.venv/lib/python3.10/site-packages/httpcore/_exceptions.py\", line 14, in map_exceptions\n    raise to_exc(exc) from exc\nhttpcore.ReadTimeout\n\nThe above exception was the direct cause of the following exception:\n\nTraceback (most recent call last):\n  File \"/work/rleap1/leon.hamm/bachelor-thesis-dev/novelty_tot/.venv/lib/python3.10/site-packages/openai/_base_client.py\", line 1526, in request\n    response = await self._client.send(\n  File \"/work/rleap1/leon.hamm/bachelor-thesis-dev/novelty_tot/.venv/lib/python3.10/site-packages/httpx/_client.py\", line 1629, in send\n    response = await self._send_handling_auth(\n  File \"/work/rleap1/leon.hamm/bachelor-thesis-dev/novelty_tot/.venv/lib/python3.10/site-packages/httpx/_client.py\", line 1657, in _send_handling_auth\n    response = await self._send_handling_redirects(\n  File \"/work/rleap1/leon.hamm/bachelor-thesis-dev/novelty_tot/.venv/lib/python3.10/site-packages/httpx/_client.py\", line 1694, in _send_handling_redirects\n    response = await self._send_single_request(request)\n  File \"/work/rleap1/leon.hamm/bachelor-thesis-dev/novelty_tot/.venv/lib/python3.10/site-packages/httpx/_client.py\", line 1730, in _send_single_request\n    response = await transport.handle_async_request(request)\n  File \"/work/rleap1/leon.hamm/bachelor-thesis-dev/novelty_tot/.venv/lib/python3.10/site-packages/httpx/_transports/default.py\", line 393, in handle_async_request\n    with map_httpcore_exceptions():\n  File \"/usr/lib/python3.10/contextlib.py\", line 153, in __exit__\n    self.gen.throw(typ, value, traceback)\n  File \"/work/rleap1/leon.hamm/bachelor-thesis-dev/novelty_tot/.venv/lib/python3.10/site-packages/httpx/_transports/default.py\", line 118, in map_httpcore_exceptions\n    raise mapped_exc(message) from exc\nhttpx.ReadTimeout\n\nThe above exception was the direct cause of the following exception:\n\nTraceback (most recent call last):\n  File \"/work/rleap1/leon.hamm/bachelor-thesis-dev/novelty_tot/tot_tester.py\", line 504, in run_math_task_with_error_handling\n    answer = await tot.run(query, parallel=parallel, breadth_first=breadth_first, problem_width=problem_width)\n  File \"/work/rleap1/leon.hamm/bachelor-thesis-dev/novelty_tot/tot.py\", line 233, in run\n    await self._expand_depth_first(self.init_state, self.max_depth, parallel=parallel)\n  File \"/work/rleap1/leon.hamm/bachelor-thesis-dev/novelty_tot/tot.py\", line 305, in _expand_depth_first\n    await self._expand_node(state, depth=depth, parallel=parallel)\n  File \"/work/rleap1/leon.hamm/bachelor-thesis-dev/novelty_tot/tot.py\", line 279, in _expand_node\n    results = await asyncio.gather(*scheduled)\n  File \"/work/rleap1/leon.hamm/bachelor-thesis-dev/novelty_tot/tot.py\", line 265, in process_branch\n    succ = await self._generate_successor(node)\n  File \"/work/rleap1/leon.hamm/bachelor-thesis-dev/novelty_tot/tot.py\", line 426, in _generate_successor\n    response = await self.query(complete_prompt)\n  File \"/work/rleap1/leon.hamm/bachelor-thesis-dev/novelty_tot/tot.py\", line 193, in query\n    response = await self.llm_engine.query(query)\n  File \"/work/rleap1/leon.hamm/bachelor-thesis-dev/novelty_tot/llm_engine.py\", line 203, in query\n    response = await client.aquery(\n  File \"/work/rleap1/leon.hamm/bachelor-thesis-dev/novelty_tot/llm_engine.py\", line 88, in aquery\n    response = await self.chat.completions.create(\n  File \"/work/rleap1/leon.hamm/bachelor-thesis-dev/novelty_tot/.venv/lib/python3.10/site-packages/openai/resources/chat/completions/completions.py\", line 2454, in create\n    return await self._post(\n  File \"/work/rleap1/leon.hamm/bachelor-thesis-dev/novelty_tot/.venv/lib/python3.10/site-packages/openai/_base_client.py\", line 1791, in post\n    return await self.request(cast_to, opts, stream=stream, stream_cls=stream_cls)\n  File \"/work/rleap1/leon.hamm/bachelor-thesis-dev/novelty_tot/.venv/lib/python3.10/site-packages/openai/_base_client.py\", line 1544, in request\n    raise APITimeoutError(request=request) from err\nopenai.APITimeoutError: Request timed out.\n",
            "token_usage": 0,
            "num_times_pruned": 0
        },
        {
            "task_id": "20",
            "success": true,
            "answer": "1 + \u221a3",
            "token_usage": 11506,
            "num_times_pruned": 0
        },
        {
            "task_id": "21",
            "success": true,
            "answer": "$\\boxed{\\dfrac{1}{2}}$",
            "token_usage": 7185,
            "num_times_pruned": 0
        },
        {
            "task_id": "22",
            "success": true,
            "answer": "-50",
            "token_usage": 16326,
            "num_times_pruned": 0
        },
        {
            "task_id": "23",
            "success": true,
            "answer": "6",
            "token_usage": 11784,
            "num_times_pruned": 0
        },
        {
            "task_id": "24",
            "success": true,
            "answer": "90",
            "token_usage": 10949,
            "num_times_pruned": 0
        },
        {
            "task_id": "25",
            "success": false,
            "answer": "Error occurred: APITimeoutError: Request timed out.\nTraceback:\nTraceback (most recent call last):\n  File \"/work/rleap1/leon.hamm/bachelor-thesis-dev/novelty_tot/.venv/lib/python3.10/site-packages/httpx/_transports/default.py\", line 101, in map_httpcore_exceptions\n    yield\n  File \"/work/rleap1/leon.hamm/bachelor-thesis-dev/novelty_tot/.venv/lib/python3.10/site-packages/httpx/_transports/default.py\", line 394, in handle_async_request\n    resp = await self._pool.handle_async_request(req)\n  File \"/work/rleap1/leon.hamm/bachelor-thesis-dev/novelty_tot/.venv/lib/python3.10/site-packages/httpcore/_async/connection_pool.py\", line 256, in handle_async_request\n    raise exc from None\n  File \"/work/rleap1/leon.hamm/bachelor-thesis-dev/novelty_tot/.venv/lib/python3.10/site-packages/httpcore/_async/connection_pool.py\", line 236, in handle_async_request\n    response = await connection.handle_async_request(\n  File \"/work/rleap1/leon.hamm/bachelor-thesis-dev/novelty_tot/.venv/lib/python3.10/site-packages/httpcore/_async/connection.py\", line 103, in handle_async_request\n    return await self._connection.handle_async_request(request)\n  File \"/work/rleap1/leon.hamm/bachelor-thesis-dev/novelty_tot/.venv/lib/python3.10/site-packages/httpcore/_async/http11.py\", line 136, in handle_async_request\n    raise exc\n  File \"/work/rleap1/leon.hamm/bachelor-thesis-dev/novelty_tot/.venv/lib/python3.10/site-packages/httpcore/_async/http11.py\", line 106, in handle_async_request\n    ) = await self._receive_response_headers(**kwargs)\n  File \"/work/rleap1/leon.hamm/bachelor-thesis-dev/novelty_tot/.venv/lib/python3.10/site-packages/httpcore/_async/http11.py\", line 177, in _receive_response_headers\n    event = await self._receive_event(timeout=timeout)\n  File \"/work/rleap1/leon.hamm/bachelor-thesis-dev/novelty_tot/.venv/lib/python3.10/site-packages/httpcore/_async/http11.py\", line 217, in _receive_event\n    data = await self._network_stream.read(\n  File \"/work/rleap1/leon.hamm/bachelor-thesis-dev/novelty_tot/.venv/lib/python3.10/site-packages/httpcore/_backends/anyio.py\", line 32, in read\n    with map_exceptions(exc_map):\n  File \"/usr/lib/python3.10/contextlib.py\", line 153, in __exit__\n    self.gen.throw(typ, value, traceback)\n  File \"/work/rleap1/leon.hamm/bachelor-thesis-dev/novelty_tot/.venv/lib/python3.10/site-packages/httpcore/_exceptions.py\", line 14, in map_exceptions\n    raise to_exc(exc) from exc\nhttpcore.ReadTimeout\n\nThe above exception was the direct cause of the following exception:\n\nTraceback (most recent call last):\n  File \"/work/rleap1/leon.hamm/bachelor-thesis-dev/novelty_tot/.venv/lib/python3.10/site-packages/openai/_base_client.py\", line 1526, in request\n    response = await self._client.send(\n  File \"/work/rleap1/leon.hamm/bachelor-thesis-dev/novelty_tot/.venv/lib/python3.10/site-packages/httpx/_client.py\", line 1629, in send\n    response = await self._send_handling_auth(\n  File \"/work/rleap1/leon.hamm/bachelor-thesis-dev/novelty_tot/.venv/lib/python3.10/site-packages/httpx/_client.py\", line 1657, in _send_handling_auth\n    response = await self._send_handling_redirects(\n  File \"/work/rleap1/leon.hamm/bachelor-thesis-dev/novelty_tot/.venv/lib/python3.10/site-packages/httpx/_client.py\", line 1694, in _send_handling_redirects\n    response = await self._send_single_request(request)\n  File \"/work/rleap1/leon.hamm/bachelor-thesis-dev/novelty_tot/.venv/lib/python3.10/site-packages/httpx/_client.py\", line 1730, in _send_single_request\n    response = await transport.handle_async_request(request)\n  File \"/work/rleap1/leon.hamm/bachelor-thesis-dev/novelty_tot/.venv/lib/python3.10/site-packages/httpx/_transports/default.py\", line 393, in handle_async_request\n    with map_httpcore_exceptions():\n  File \"/usr/lib/python3.10/contextlib.py\", line 153, in __exit__\n    self.gen.throw(typ, value, traceback)\n  File \"/work/rleap1/leon.hamm/bachelor-thesis-dev/novelty_tot/.venv/lib/python3.10/site-packages/httpx/_transports/default.py\", line 118, in map_httpcore_exceptions\n    raise mapped_exc(message) from exc\nhttpx.ReadTimeout\n\nThe above exception was the direct cause of the following exception:\n\nTraceback (most recent call last):\n  File \"/work/rleap1/leon.hamm/bachelor-thesis-dev/novelty_tot/tot_tester.py\", line 504, in run_math_task_with_error_handling\n    answer = await tot.run(query, parallel=parallel, breadth_first=breadth_first, problem_width=problem_width)\n  File \"/work/rleap1/leon.hamm/bachelor-thesis-dev/novelty_tot/tot.py\", line 233, in run\n    await self._expand_depth_first(self.init_state, self.max_depth, parallel=parallel)\n  File \"/work/rleap1/leon.hamm/bachelor-thesis-dev/novelty_tot/tot.py\", line 305, in _expand_depth_first\n    await self._expand_node(state, depth=depth, parallel=parallel)\n  File \"/work/rleap1/leon.hamm/bachelor-thesis-dev/novelty_tot/tot.py\", line 279, in _expand_node\n    results = await asyncio.gather(*scheduled)\n  File \"/work/rleap1/leon.hamm/bachelor-thesis-dev/novelty_tot/tot.py\", line 265, in process_branch\n    succ = await self._generate_successor(node)\n  File \"/work/rleap1/leon.hamm/bachelor-thesis-dev/novelty_tot/tot.py\", line 426, in _generate_successor\n    response = await self.query(complete_prompt)\n  File \"/work/rleap1/leon.hamm/bachelor-thesis-dev/novelty_tot/tot.py\", line 193, in query\n    response = await self.llm_engine.query(query)\n  File \"/work/rleap1/leon.hamm/bachelor-thesis-dev/novelty_tot/llm_engine.py\", line 203, in query\n    response = await client.aquery(\n  File \"/work/rleap1/leon.hamm/bachelor-thesis-dev/novelty_tot/llm_engine.py\", line 88, in aquery\n    response = await self.chat.completions.create(\n  File \"/work/rleap1/leon.hamm/bachelor-thesis-dev/novelty_tot/.venv/lib/python3.10/site-packages/openai/resources/chat/completions/completions.py\", line 2454, in create\n    return await self._post(\n  File \"/work/rleap1/leon.hamm/bachelor-thesis-dev/novelty_tot/.venv/lib/python3.10/site-packages/openai/_base_client.py\", line 1791, in post\n    return await self.request(cast_to, opts, stream=stream, stream_cls=stream_cls)\n  File \"/work/rleap1/leon.hamm/bachelor-thesis-dev/novelty_tot/.venv/lib/python3.10/site-packages/openai/_base_client.py\", line 1544, in request\n    raise APITimeoutError(request=request) from err\nopenai.APITimeoutError: Request timed out.\n",
            "token_usage": 0,
            "num_times_pruned": 0
        },
        {
            "task_id": "26",
            "success": false,
            "answer": "Error occurred: APITimeoutError: Request timed out.\nTraceback:\nTraceback (most recent call last):\n  File \"/work/rleap1/leon.hamm/bachelor-thesis-dev/novelty_tot/.venv/lib/python3.10/site-packages/httpx/_transports/default.py\", line 101, in map_httpcore_exceptions\n    yield\n  File \"/work/rleap1/leon.hamm/bachelor-thesis-dev/novelty_tot/.venv/lib/python3.10/site-packages/httpx/_transports/default.py\", line 394, in handle_async_request\n    resp = await self._pool.handle_async_request(req)\n  File \"/work/rleap1/leon.hamm/bachelor-thesis-dev/novelty_tot/.venv/lib/python3.10/site-packages/httpcore/_async/connection_pool.py\", line 256, in handle_async_request\n    raise exc from None\n  File \"/work/rleap1/leon.hamm/bachelor-thesis-dev/novelty_tot/.venv/lib/python3.10/site-packages/httpcore/_async/connection_pool.py\", line 236, in handle_async_request\n    response = await connection.handle_async_request(\n  File \"/work/rleap1/leon.hamm/bachelor-thesis-dev/novelty_tot/.venv/lib/python3.10/site-packages/httpcore/_async/connection.py\", line 103, in handle_async_request\n    return await self._connection.handle_async_request(request)\n  File \"/work/rleap1/leon.hamm/bachelor-thesis-dev/novelty_tot/.venv/lib/python3.10/site-packages/httpcore/_async/http11.py\", line 136, in handle_async_request\n    raise exc\n  File \"/work/rleap1/leon.hamm/bachelor-thesis-dev/novelty_tot/.venv/lib/python3.10/site-packages/httpcore/_async/http11.py\", line 106, in handle_async_request\n    ) = await self._receive_response_headers(**kwargs)\n  File \"/work/rleap1/leon.hamm/bachelor-thesis-dev/novelty_tot/.venv/lib/python3.10/site-packages/httpcore/_async/http11.py\", line 177, in _receive_response_headers\n    event = await self._receive_event(timeout=timeout)\n  File \"/work/rleap1/leon.hamm/bachelor-thesis-dev/novelty_tot/.venv/lib/python3.10/site-packages/httpcore/_async/http11.py\", line 217, in _receive_event\n    data = await self._network_stream.read(\n  File \"/work/rleap1/leon.hamm/bachelor-thesis-dev/novelty_tot/.venv/lib/python3.10/site-packages/httpcore/_backends/anyio.py\", line 32, in read\n    with map_exceptions(exc_map):\n  File \"/usr/lib/python3.10/contextlib.py\", line 153, in __exit__\n    self.gen.throw(typ, value, traceback)\n  File \"/work/rleap1/leon.hamm/bachelor-thesis-dev/novelty_tot/.venv/lib/python3.10/site-packages/httpcore/_exceptions.py\", line 14, in map_exceptions\n    raise to_exc(exc) from exc\nhttpcore.ReadTimeout\n\nThe above exception was the direct cause of the following exception:\n\nTraceback (most recent call last):\n  File \"/work/rleap1/leon.hamm/bachelor-thesis-dev/novelty_tot/.venv/lib/python3.10/site-packages/openai/_base_client.py\", line 1526, in request\n    response = await self._client.send(\n  File \"/work/rleap1/leon.hamm/bachelor-thesis-dev/novelty_tot/.venv/lib/python3.10/site-packages/httpx/_client.py\", line 1629, in send\n    response = await self._send_handling_auth(\n  File \"/work/rleap1/leon.hamm/bachelor-thesis-dev/novelty_tot/.venv/lib/python3.10/site-packages/httpx/_client.py\", line 1657, in _send_handling_auth\n    response = await self._send_handling_redirects(\n  File \"/work/rleap1/leon.hamm/bachelor-thesis-dev/novelty_tot/.venv/lib/python3.10/site-packages/httpx/_client.py\", line 1694, in _send_handling_redirects\n    response = await self._send_single_request(request)\n  File \"/work/rleap1/leon.hamm/bachelor-thesis-dev/novelty_tot/.venv/lib/python3.10/site-packages/httpx/_client.py\", line 1730, in _send_single_request\n    response = await transport.handle_async_request(request)\n  File \"/work/rleap1/leon.hamm/bachelor-thesis-dev/novelty_tot/.venv/lib/python3.10/site-packages/httpx/_transports/default.py\", line 393, in handle_async_request\n    with map_httpcore_exceptions():\n  File \"/usr/lib/python3.10/contextlib.py\", line 153, in __exit__\n    self.gen.throw(typ, value, traceback)\n  File \"/work/rleap1/leon.hamm/bachelor-thesis-dev/novelty_tot/.venv/lib/python3.10/site-packages/httpx/_transports/default.py\", line 118, in map_httpcore_exceptions\n    raise mapped_exc(message) from exc\nhttpx.ReadTimeout\n\nThe above exception was the direct cause of the following exception:\n\nTraceback (most recent call last):\n  File \"/work/rleap1/leon.hamm/bachelor-thesis-dev/novelty_tot/tot_tester.py\", line 504, in run_math_task_with_error_handling\n    answer = await tot.run(query, parallel=parallel, breadth_first=breadth_first, problem_width=problem_width)\n  File \"/work/rleap1/leon.hamm/bachelor-thesis-dev/novelty_tot/tot.py\", line 233, in run\n    await self._expand_depth_first(self.init_state, self.max_depth, parallel=parallel)\n  File \"/work/rleap1/leon.hamm/bachelor-thesis-dev/novelty_tot/tot.py\", line 305, in _expand_depth_first\n    await self._expand_node(state, depth=depth, parallel=parallel)\n  File \"/work/rleap1/leon.hamm/bachelor-thesis-dev/novelty_tot/tot.py\", line 279, in _expand_node\n    results = await asyncio.gather(*scheduled)\n  File \"/work/rleap1/leon.hamm/bachelor-thesis-dev/novelty_tot/tot.py\", line 265, in process_branch\n    succ = await self._generate_successor(node)\n  File \"/work/rleap1/leon.hamm/bachelor-thesis-dev/novelty_tot/tot.py\", line 426, in _generate_successor\n    response = await self.query(complete_prompt)\n  File \"/work/rleap1/leon.hamm/bachelor-thesis-dev/novelty_tot/tot.py\", line 193, in query\n    response = await self.llm_engine.query(query)\n  File \"/work/rleap1/leon.hamm/bachelor-thesis-dev/novelty_tot/llm_engine.py\", line 203, in query\n    response = await client.aquery(\n  File \"/work/rleap1/leon.hamm/bachelor-thesis-dev/novelty_tot/llm_engine.py\", line 88, in aquery\n    response = await self.chat.completions.create(\n  File \"/work/rleap1/leon.hamm/bachelor-thesis-dev/novelty_tot/.venv/lib/python3.10/site-packages/openai/resources/chat/completions/completions.py\", line 2454, in create\n    return await self._post(\n  File \"/work/rleap1/leon.hamm/bachelor-thesis-dev/novelty_tot/.venv/lib/python3.10/site-packages/openai/_base_client.py\", line 1791, in post\n    return await self.request(cast_to, opts, stream=stream, stream_cls=stream_cls)\n  File \"/work/rleap1/leon.hamm/bachelor-thesis-dev/novelty_tot/.venv/lib/python3.10/site-packages/openai/_base_client.py\", line 1544, in request\n    raise APITimeoutError(request=request) from err\nopenai.APITimeoutError: Request timed out.\n",
            "token_usage": 0,
            "num_times_pruned": 0
        },
        {
            "task_id": "27",
            "success": true,
            "answer": "6",
            "token_usage": 4917,
            "num_times_pruned": 0
        },
        {
            "task_id": "28",
            "success": true,
            "answer": "The domain is $ (-\\infty, -1) \\cup (4, \\infty) $.",
            "token_usage": 4171,
            "num_times_pruned": 0
        },
        {
            "task_id": "29",
            "success": true,
            "answer": "36",
            "token_usage": 10293,
            "num_times_pruned": 0
        },
        {
            "task_id": "30",
            "success": true,
            "answer": "1016",
            "token_usage": 10098,
            "num_times_pruned": 0
        },
        {
            "task_id": "31",
            "success": false,
            "answer": "Error occurred: APITimeoutError: Request timed out.\nTraceback:\nTraceback (most recent call last):\n  File \"/work/rleap1/leon.hamm/bachelor-thesis-dev/novelty_tot/.venv/lib/python3.10/site-packages/httpx/_transports/default.py\", line 101, in map_httpcore_exceptions\n    yield\n  File \"/work/rleap1/leon.hamm/bachelor-thesis-dev/novelty_tot/.venv/lib/python3.10/site-packages/httpx/_transports/default.py\", line 394, in handle_async_request\n    resp = await self._pool.handle_async_request(req)\n  File \"/work/rleap1/leon.hamm/bachelor-thesis-dev/novelty_tot/.venv/lib/python3.10/site-packages/httpcore/_async/connection_pool.py\", line 256, in handle_async_request\n    raise exc from None\n  File \"/work/rleap1/leon.hamm/bachelor-thesis-dev/novelty_tot/.venv/lib/python3.10/site-packages/httpcore/_async/connection_pool.py\", line 236, in handle_async_request\n    response = await connection.handle_async_request(\n  File \"/work/rleap1/leon.hamm/bachelor-thesis-dev/novelty_tot/.venv/lib/python3.10/site-packages/httpcore/_async/connection.py\", line 103, in handle_async_request\n    return await self._connection.handle_async_request(request)\n  File \"/work/rleap1/leon.hamm/bachelor-thesis-dev/novelty_tot/.venv/lib/python3.10/site-packages/httpcore/_async/http11.py\", line 136, in handle_async_request\n    raise exc\n  File \"/work/rleap1/leon.hamm/bachelor-thesis-dev/novelty_tot/.venv/lib/python3.10/site-packages/httpcore/_async/http11.py\", line 106, in handle_async_request\n    ) = await self._receive_response_headers(**kwargs)\n  File \"/work/rleap1/leon.hamm/bachelor-thesis-dev/novelty_tot/.venv/lib/python3.10/site-packages/httpcore/_async/http11.py\", line 177, in _receive_response_headers\n    event = await self._receive_event(timeout=timeout)\n  File \"/work/rleap1/leon.hamm/bachelor-thesis-dev/novelty_tot/.venv/lib/python3.10/site-packages/httpcore/_async/http11.py\", line 217, in _receive_event\n    data = await self._network_stream.read(\n  File \"/work/rleap1/leon.hamm/bachelor-thesis-dev/novelty_tot/.venv/lib/python3.10/site-packages/httpcore/_backends/anyio.py\", line 32, in read\n    with map_exceptions(exc_map):\n  File \"/usr/lib/python3.10/contextlib.py\", line 153, in __exit__\n    self.gen.throw(typ, value, traceback)\n  File \"/work/rleap1/leon.hamm/bachelor-thesis-dev/novelty_tot/.venv/lib/python3.10/site-packages/httpcore/_exceptions.py\", line 14, in map_exceptions\n    raise to_exc(exc) from exc\nhttpcore.ReadTimeout\n\nThe above exception was the direct cause of the following exception:\n\nTraceback (most recent call last):\n  File \"/work/rleap1/leon.hamm/bachelor-thesis-dev/novelty_tot/.venv/lib/python3.10/site-packages/openai/_base_client.py\", line 1526, in request\n    response = await self._client.send(\n  File \"/work/rleap1/leon.hamm/bachelor-thesis-dev/novelty_tot/.venv/lib/python3.10/site-packages/httpx/_client.py\", line 1629, in send\n    response = await self._send_handling_auth(\n  File \"/work/rleap1/leon.hamm/bachelor-thesis-dev/novelty_tot/.venv/lib/python3.10/site-packages/httpx/_client.py\", line 1657, in _send_handling_auth\n    response = await self._send_handling_redirects(\n  File \"/work/rleap1/leon.hamm/bachelor-thesis-dev/novelty_tot/.venv/lib/python3.10/site-packages/httpx/_client.py\", line 1694, in _send_handling_redirects\n    response = await self._send_single_request(request)\n  File \"/work/rleap1/leon.hamm/bachelor-thesis-dev/novelty_tot/.venv/lib/python3.10/site-packages/httpx/_client.py\", line 1730, in _send_single_request\n    response = await transport.handle_async_request(request)\n  File \"/work/rleap1/leon.hamm/bachelor-thesis-dev/novelty_tot/.venv/lib/python3.10/site-packages/httpx/_transports/default.py\", line 393, in handle_async_request\n    with map_httpcore_exceptions():\n  File \"/usr/lib/python3.10/contextlib.py\", line 153, in __exit__\n    self.gen.throw(typ, value, traceback)\n  File \"/work/rleap1/leon.hamm/bachelor-thesis-dev/novelty_tot/.venv/lib/python3.10/site-packages/httpx/_transports/default.py\", line 118, in map_httpcore_exceptions\n    raise mapped_exc(message) from exc\nhttpx.ReadTimeout\n\nThe above exception was the direct cause of the following exception:\n\nTraceback (most recent call last):\n  File \"/work/rleap1/leon.hamm/bachelor-thesis-dev/novelty_tot/tot_tester.py\", line 504, in run_math_task_with_error_handling\n    answer = await tot.run(query, parallel=parallel, breadth_first=breadth_first, problem_width=problem_width)\n  File \"/work/rleap1/leon.hamm/bachelor-thesis-dev/novelty_tot/tot.py\", line 233, in run\n    await self._expand_depth_first(self.init_state, self.max_depth, parallel=parallel)\n  File \"/work/rleap1/leon.hamm/bachelor-thesis-dev/novelty_tot/tot.py\", line 305, in _expand_depth_first\n    await self._expand_node(state, depth=depth, parallel=parallel)\n  File \"/work/rleap1/leon.hamm/bachelor-thesis-dev/novelty_tot/tot.py\", line 279, in _expand_node\n    results = await asyncio.gather(*scheduled)\n  File \"/work/rleap1/leon.hamm/bachelor-thesis-dev/novelty_tot/tot.py\", line 265, in process_branch\n    succ = await self._generate_successor(node)\n  File \"/work/rleap1/leon.hamm/bachelor-thesis-dev/novelty_tot/tot.py\", line 426, in _generate_successor\n    response = await self.query(complete_prompt)\n  File \"/work/rleap1/leon.hamm/bachelor-thesis-dev/novelty_tot/tot.py\", line 193, in query\n    response = await self.llm_engine.query(query)\n  File \"/work/rleap1/leon.hamm/bachelor-thesis-dev/novelty_tot/llm_engine.py\", line 203, in query\n    response = await client.aquery(\n  File \"/work/rleap1/leon.hamm/bachelor-thesis-dev/novelty_tot/llm_engine.py\", line 88, in aquery\n    response = await self.chat.completions.create(\n  File \"/work/rleap1/leon.hamm/bachelor-thesis-dev/novelty_tot/.venv/lib/python3.10/site-packages/openai/resources/chat/completions/completions.py\", line 2454, in create\n    return await self._post(\n  File \"/work/rleap1/leon.hamm/bachelor-thesis-dev/novelty_tot/.venv/lib/python3.10/site-packages/openai/_base_client.py\", line 1791, in post\n    return await self.request(cast_to, opts, stream=stream, stream_cls=stream_cls)\n  File \"/work/rleap1/leon.hamm/bachelor-thesis-dev/novelty_tot/.venv/lib/python3.10/site-packages/openai/_base_client.py\", line 1544, in request\n    raise APITimeoutError(request=request) from err\nopenai.APITimeoutError: Request timed out.\n",
            "token_usage": 0,
            "num_times_pruned": 0
        },
        {
            "task_id": "32",
            "success": true,
            "answer": "D",
            "token_usage": 6235,
            "num_times_pruned": 0
        },
        {
            "task_id": "33",
            "success": true,
            "answer": "35",
            "token_usage": 3839,
            "num_times_pruned": 0
        },
        {
            "task_id": "34",
            "success": true,
            "answer": "-3",
            "token_usage": 4612,
            "num_times_pruned": 0
        },
        {
            "task_id": "35",
            "success": true,
            "answer": "182",
            "token_usage": 6336,
            "num_times_pruned": 0
        },
        {
            "task_id": "36",
            "success": true,
            "answer": "89,88,85,73,70",
            "token_usage": 5669,
            "num_times_pruned": 0
        },
        {
            "task_id": "37",
            "success": true,
            "answer": "3 + 6\u221a2",
            "token_usage": 16160,
            "num_times_pruned": 0
        },
        {
            "task_id": "38",
            "success": false,
            "answer": "Error occurred: APITimeoutError: Request timed out.\nTraceback:\nTraceback (most recent call last):\n  File \"/work/rleap1/leon.hamm/bachelor-thesis-dev/novelty_tot/.venv/lib/python3.10/site-packages/httpx/_transports/default.py\", line 101, in map_httpcore_exceptions\n    yield\n  File \"/work/rleap1/leon.hamm/bachelor-thesis-dev/novelty_tot/.venv/lib/python3.10/site-packages/httpx/_transports/default.py\", line 394, in handle_async_request\n    resp = await self._pool.handle_async_request(req)\n  File \"/work/rleap1/leon.hamm/bachelor-thesis-dev/novelty_tot/.venv/lib/python3.10/site-packages/httpcore/_async/connection_pool.py\", line 256, in handle_async_request\n    raise exc from None\n  File \"/work/rleap1/leon.hamm/bachelor-thesis-dev/novelty_tot/.venv/lib/python3.10/site-packages/httpcore/_async/connection_pool.py\", line 236, in handle_async_request\n    response = await connection.handle_async_request(\n  File \"/work/rleap1/leon.hamm/bachelor-thesis-dev/novelty_tot/.venv/lib/python3.10/site-packages/httpcore/_async/connection.py\", line 103, in handle_async_request\n    return await self._connection.handle_async_request(request)\n  File \"/work/rleap1/leon.hamm/bachelor-thesis-dev/novelty_tot/.venv/lib/python3.10/site-packages/httpcore/_async/http11.py\", line 136, in handle_async_request\n    raise exc\n  File \"/work/rleap1/leon.hamm/bachelor-thesis-dev/novelty_tot/.venv/lib/python3.10/site-packages/httpcore/_async/http11.py\", line 106, in handle_async_request\n    ) = await self._receive_response_headers(**kwargs)\n  File \"/work/rleap1/leon.hamm/bachelor-thesis-dev/novelty_tot/.venv/lib/python3.10/site-packages/httpcore/_async/http11.py\", line 177, in _receive_response_headers\n    event = await self._receive_event(timeout=timeout)\n  File \"/work/rleap1/leon.hamm/bachelor-thesis-dev/novelty_tot/.venv/lib/python3.10/site-packages/httpcore/_async/http11.py\", line 217, in _receive_event\n    data = await self._network_stream.read(\n  File \"/work/rleap1/leon.hamm/bachelor-thesis-dev/novelty_tot/.venv/lib/python3.10/site-packages/httpcore/_backends/anyio.py\", line 32, in read\n    with map_exceptions(exc_map):\n  File \"/usr/lib/python3.10/contextlib.py\", line 153, in __exit__\n    self.gen.throw(typ, value, traceback)\n  File \"/work/rleap1/leon.hamm/bachelor-thesis-dev/novelty_tot/.venv/lib/python3.10/site-packages/httpcore/_exceptions.py\", line 14, in map_exceptions\n    raise to_exc(exc) from exc\nhttpcore.ReadTimeout\n\nThe above exception was the direct cause of the following exception:\n\nTraceback (most recent call last):\n  File \"/work/rleap1/leon.hamm/bachelor-thesis-dev/novelty_tot/.venv/lib/python3.10/site-packages/openai/_base_client.py\", line 1526, in request\n    response = await self._client.send(\n  File \"/work/rleap1/leon.hamm/bachelor-thesis-dev/novelty_tot/.venv/lib/python3.10/site-packages/httpx/_client.py\", line 1629, in send\n    response = await self._send_handling_auth(\n  File \"/work/rleap1/leon.hamm/bachelor-thesis-dev/novelty_tot/.venv/lib/python3.10/site-packages/httpx/_client.py\", line 1657, in _send_handling_auth\n    response = await self._send_handling_redirects(\n  File \"/work/rleap1/leon.hamm/bachelor-thesis-dev/novelty_tot/.venv/lib/python3.10/site-packages/httpx/_client.py\", line 1694, in _send_handling_redirects\n    response = await self._send_single_request(request)\n  File \"/work/rleap1/leon.hamm/bachelor-thesis-dev/novelty_tot/.venv/lib/python3.10/site-packages/httpx/_client.py\", line 1730, in _send_single_request\n    response = await transport.handle_async_request(request)\n  File \"/work/rleap1/leon.hamm/bachelor-thesis-dev/novelty_tot/.venv/lib/python3.10/site-packages/httpx/_transports/default.py\", line 393, in handle_async_request\n    with map_httpcore_exceptions():\n  File \"/usr/lib/python3.10/contextlib.py\", line 153, in __exit__\n    self.gen.throw(typ, value, traceback)\n  File \"/work/rleap1/leon.hamm/bachelor-thesis-dev/novelty_tot/.venv/lib/python3.10/site-packages/httpx/_transports/default.py\", line 118, in map_httpcore_exceptions\n    raise mapped_exc(message) from exc\nhttpx.ReadTimeout\n\nThe above exception was the direct cause of the following exception:\n\nTraceback (most recent call last):\n  File \"/work/rleap1/leon.hamm/bachelor-thesis-dev/novelty_tot/tot_tester.py\", line 504, in run_math_task_with_error_handling\n    answer = await tot.run(query, parallel=parallel, breadth_first=breadth_first, problem_width=problem_width)\n  File \"/work/rleap1/leon.hamm/bachelor-thesis-dev/novelty_tot/tot.py\", line 233, in run\n    await self._expand_depth_first(self.init_state, self.max_depth, parallel=parallel)\n  File \"/work/rleap1/leon.hamm/bachelor-thesis-dev/novelty_tot/tot.py\", line 305, in _expand_depth_first\n    await self._expand_node(state, depth=depth, parallel=parallel)\n  File \"/work/rleap1/leon.hamm/bachelor-thesis-dev/novelty_tot/tot.py\", line 279, in _expand_node\n    results = await asyncio.gather(*scheduled)\n  File \"/work/rleap1/leon.hamm/bachelor-thesis-dev/novelty_tot/tot.py\", line 265, in process_branch\n    succ = await self._generate_successor(node)\n  File \"/work/rleap1/leon.hamm/bachelor-thesis-dev/novelty_tot/tot.py\", line 426, in _generate_successor\n    response = await self.query(complete_prompt)\n  File \"/work/rleap1/leon.hamm/bachelor-thesis-dev/novelty_tot/tot.py\", line 193, in query\n    response = await self.llm_engine.query(query)\n  File \"/work/rleap1/leon.hamm/bachelor-thesis-dev/novelty_tot/llm_engine.py\", line 203, in query\n    response = await client.aquery(\n  File \"/work/rleap1/leon.hamm/bachelor-thesis-dev/novelty_tot/llm_engine.py\", line 88, in aquery\n    response = await self.chat.completions.create(\n  File \"/work/rleap1/leon.hamm/bachelor-thesis-dev/novelty_tot/.venv/lib/python3.10/site-packages/openai/resources/chat/completions/completions.py\", line 2454, in create\n    return await self._post(\n  File \"/work/rleap1/leon.hamm/bachelor-thesis-dev/novelty_tot/.venv/lib/python3.10/site-packages/openai/_base_client.py\", line 1791, in post\n    return await self.request(cast_to, opts, stream=stream, stream_cls=stream_cls)\n  File \"/work/rleap1/leon.hamm/bachelor-thesis-dev/novelty_tot/.venv/lib/python3.10/site-packages/openai/_base_client.py\", line 1544, in request\n    raise APITimeoutError(request=request) from err\nopenai.APITimeoutError: Request timed out.\n",
            "token_usage": 0,
            "num_times_pruned": 0
        },
        {
            "task_id": "39",
            "success": true,
            "answer": "230769",
            "token_usage": 11634,
            "num_times_pruned": 0
        },
        {
            "task_id": "40",
            "success": true,
            "answer": "28",
            "token_usage": 12284,
            "num_times_pruned": 0
        },
        {
            "task_id": "41",
            "success": false,
            "answer": "Error occurred: APITimeoutError: Request timed out.\nTraceback:\nTraceback (most recent call last):\n  File \"/work/rleap1/leon.hamm/bachelor-thesis-dev/novelty_tot/.venv/lib/python3.10/site-packages/httpx/_transports/default.py\", line 101, in map_httpcore_exceptions\n    yield\n  File \"/work/rleap1/leon.hamm/bachelor-thesis-dev/novelty_tot/.venv/lib/python3.10/site-packages/httpx/_transports/default.py\", line 394, in handle_async_request\n    resp = await self._pool.handle_async_request(req)\n  File \"/work/rleap1/leon.hamm/bachelor-thesis-dev/novelty_tot/.venv/lib/python3.10/site-packages/httpcore/_async/connection_pool.py\", line 256, in handle_async_request\n    raise exc from None\n  File \"/work/rleap1/leon.hamm/bachelor-thesis-dev/novelty_tot/.venv/lib/python3.10/site-packages/httpcore/_async/connection_pool.py\", line 236, in handle_async_request\n    response = await connection.handle_async_request(\n  File \"/work/rleap1/leon.hamm/bachelor-thesis-dev/novelty_tot/.venv/lib/python3.10/site-packages/httpcore/_async/connection.py\", line 103, in handle_async_request\n    return await self._connection.handle_async_request(request)\n  File \"/work/rleap1/leon.hamm/bachelor-thesis-dev/novelty_tot/.venv/lib/python3.10/site-packages/httpcore/_async/http11.py\", line 136, in handle_async_request\n    raise exc\n  File \"/work/rleap1/leon.hamm/bachelor-thesis-dev/novelty_tot/.venv/lib/python3.10/site-packages/httpcore/_async/http11.py\", line 106, in handle_async_request\n    ) = await self._receive_response_headers(**kwargs)\n  File \"/work/rleap1/leon.hamm/bachelor-thesis-dev/novelty_tot/.venv/lib/python3.10/site-packages/httpcore/_async/http11.py\", line 177, in _receive_response_headers\n    event = await self._receive_event(timeout=timeout)\n  File \"/work/rleap1/leon.hamm/bachelor-thesis-dev/novelty_tot/.venv/lib/python3.10/site-packages/httpcore/_async/http11.py\", line 217, in _receive_event\n    data = await self._network_stream.read(\n  File \"/work/rleap1/leon.hamm/bachelor-thesis-dev/novelty_tot/.venv/lib/python3.10/site-packages/httpcore/_backends/anyio.py\", line 32, in read\n    with map_exceptions(exc_map):\n  File \"/usr/lib/python3.10/contextlib.py\", line 153, in __exit__\n    self.gen.throw(typ, value, traceback)\n  File \"/work/rleap1/leon.hamm/bachelor-thesis-dev/novelty_tot/.venv/lib/python3.10/site-packages/httpcore/_exceptions.py\", line 14, in map_exceptions\n    raise to_exc(exc) from exc\nhttpcore.ReadTimeout\n\nThe above exception was the direct cause of the following exception:\n\nTraceback (most recent call last):\n  File \"/work/rleap1/leon.hamm/bachelor-thesis-dev/novelty_tot/.venv/lib/python3.10/site-packages/openai/_base_client.py\", line 1526, in request\n    response = await self._client.send(\n  File \"/work/rleap1/leon.hamm/bachelor-thesis-dev/novelty_tot/.venv/lib/python3.10/site-packages/httpx/_client.py\", line 1629, in send\n    response = await self._send_handling_auth(\n  File \"/work/rleap1/leon.hamm/bachelor-thesis-dev/novelty_tot/.venv/lib/python3.10/site-packages/httpx/_client.py\", line 1657, in _send_handling_auth\n    response = await self._send_handling_redirects(\n  File \"/work/rleap1/leon.hamm/bachelor-thesis-dev/novelty_tot/.venv/lib/python3.10/site-packages/httpx/_client.py\", line 1694, in _send_handling_redirects\n    response = await self._send_single_request(request)\n  File \"/work/rleap1/leon.hamm/bachelor-thesis-dev/novelty_tot/.venv/lib/python3.10/site-packages/httpx/_client.py\", line 1730, in _send_single_request\n    response = await transport.handle_async_request(request)\n  File \"/work/rleap1/leon.hamm/bachelor-thesis-dev/novelty_tot/.venv/lib/python3.10/site-packages/httpx/_transports/default.py\", line 393, in handle_async_request\n    with map_httpcore_exceptions():\n  File \"/usr/lib/python3.10/contextlib.py\", line 153, in __exit__\n    self.gen.throw(typ, value, traceback)\n  File \"/work/rleap1/leon.hamm/bachelor-thesis-dev/novelty_tot/.venv/lib/python3.10/site-packages/httpx/_transports/default.py\", line 118, in map_httpcore_exceptions\n    raise mapped_exc(message) from exc\nhttpx.ReadTimeout\n\nThe above exception was the direct cause of the following exception:\n\nTraceback (most recent call last):\n  File \"/work/rleap1/leon.hamm/bachelor-thesis-dev/novelty_tot/tot_tester.py\", line 504, in run_math_task_with_error_handling\n    answer = await tot.run(query, parallel=parallel, breadth_first=breadth_first, problem_width=problem_width)\n  File \"/work/rleap1/leon.hamm/bachelor-thesis-dev/novelty_tot/tot.py\", line 233, in run\n    await self._expand_depth_first(self.init_state, self.max_depth, parallel=parallel)\n  File \"/work/rleap1/leon.hamm/bachelor-thesis-dev/novelty_tot/tot.py\", line 305, in _expand_depth_first\n    await self._expand_node(state, depth=depth, parallel=parallel)\n  File \"/work/rleap1/leon.hamm/bachelor-thesis-dev/novelty_tot/tot.py\", line 279, in _expand_node\n    results = await asyncio.gather(*scheduled)\n  File \"/work/rleap1/leon.hamm/bachelor-thesis-dev/novelty_tot/tot.py\", line 265, in process_branch\n    succ = await self._generate_successor(node)\n  File \"/work/rleap1/leon.hamm/bachelor-thesis-dev/novelty_tot/tot.py\", line 426, in _generate_successor\n    response = await self.query(complete_prompt)\n  File \"/work/rleap1/leon.hamm/bachelor-thesis-dev/novelty_tot/tot.py\", line 193, in query\n    response = await self.llm_engine.query(query)\n  File \"/work/rleap1/leon.hamm/bachelor-thesis-dev/novelty_tot/llm_engine.py\", line 203, in query\n    response = await client.aquery(\n  File \"/work/rleap1/leon.hamm/bachelor-thesis-dev/novelty_tot/llm_engine.py\", line 88, in aquery\n    response = await self.chat.completions.create(\n  File \"/work/rleap1/leon.hamm/bachelor-thesis-dev/novelty_tot/.venv/lib/python3.10/site-packages/openai/resources/chat/completions/completions.py\", line 2454, in create\n    return await self._post(\n  File \"/work/rleap1/leon.hamm/bachelor-thesis-dev/novelty_tot/.venv/lib/python3.10/site-packages/openai/_base_client.py\", line 1791, in post\n    return await self.request(cast_to, opts, stream=stream, stream_cls=stream_cls)\n  File \"/work/rleap1/leon.hamm/bachelor-thesis-dev/novelty_tot/.venv/lib/python3.10/site-packages/openai/_base_client.py\", line 1544, in request\n    raise APITimeoutError(request=request) from err\nopenai.APITimeoutError: Request timed out.\n",
            "token_usage": 0,
            "num_times_pruned": 0
        },
        {
            "task_id": "42",
            "success": false,
            "answer": "Error occurred: APITimeoutError: Request timed out.\nTraceback:\nTraceback (most recent call last):\n  File \"/work/rleap1/leon.hamm/bachelor-thesis-dev/novelty_tot/.venv/lib/python3.10/site-packages/httpx/_transports/default.py\", line 101, in map_httpcore_exceptions\n    yield\n  File \"/work/rleap1/leon.hamm/bachelor-thesis-dev/novelty_tot/.venv/lib/python3.10/site-packages/httpx/_transports/default.py\", line 394, in handle_async_request\n    resp = await self._pool.handle_async_request(req)\n  File \"/work/rleap1/leon.hamm/bachelor-thesis-dev/novelty_tot/.venv/lib/python3.10/site-packages/httpcore/_async/connection_pool.py\", line 256, in handle_async_request\n    raise exc from None\n  File \"/work/rleap1/leon.hamm/bachelor-thesis-dev/novelty_tot/.venv/lib/python3.10/site-packages/httpcore/_async/connection_pool.py\", line 236, in handle_async_request\n    response = await connection.handle_async_request(\n  File \"/work/rleap1/leon.hamm/bachelor-thesis-dev/novelty_tot/.venv/lib/python3.10/site-packages/httpcore/_async/connection.py\", line 103, in handle_async_request\n    return await self._connection.handle_async_request(request)\n  File \"/work/rleap1/leon.hamm/bachelor-thesis-dev/novelty_tot/.venv/lib/python3.10/site-packages/httpcore/_async/http11.py\", line 136, in handle_async_request\n    raise exc\n  File \"/work/rleap1/leon.hamm/bachelor-thesis-dev/novelty_tot/.venv/lib/python3.10/site-packages/httpcore/_async/http11.py\", line 106, in handle_async_request\n    ) = await self._receive_response_headers(**kwargs)\n  File \"/work/rleap1/leon.hamm/bachelor-thesis-dev/novelty_tot/.venv/lib/python3.10/site-packages/httpcore/_async/http11.py\", line 177, in _receive_response_headers\n    event = await self._receive_event(timeout=timeout)\n  File \"/work/rleap1/leon.hamm/bachelor-thesis-dev/novelty_tot/.venv/lib/python3.10/site-packages/httpcore/_async/http11.py\", line 217, in _receive_event\n    data = await self._network_stream.read(\n  File \"/work/rleap1/leon.hamm/bachelor-thesis-dev/novelty_tot/.venv/lib/python3.10/site-packages/httpcore/_backends/anyio.py\", line 32, in read\n    with map_exceptions(exc_map):\n  File \"/usr/lib/python3.10/contextlib.py\", line 153, in __exit__\n    self.gen.throw(typ, value, traceback)\n  File \"/work/rleap1/leon.hamm/bachelor-thesis-dev/novelty_tot/.venv/lib/python3.10/site-packages/httpcore/_exceptions.py\", line 14, in map_exceptions\n    raise to_exc(exc) from exc\nhttpcore.ReadTimeout\n\nThe above exception was the direct cause of the following exception:\n\nTraceback (most recent call last):\n  File \"/work/rleap1/leon.hamm/bachelor-thesis-dev/novelty_tot/.venv/lib/python3.10/site-packages/openai/_base_client.py\", line 1526, in request\n    response = await self._client.send(\n  File \"/work/rleap1/leon.hamm/bachelor-thesis-dev/novelty_tot/.venv/lib/python3.10/site-packages/httpx/_client.py\", line 1629, in send\n    response = await self._send_handling_auth(\n  File \"/work/rleap1/leon.hamm/bachelor-thesis-dev/novelty_tot/.venv/lib/python3.10/site-packages/httpx/_client.py\", line 1657, in _send_handling_auth\n    response = await self._send_handling_redirects(\n  File \"/work/rleap1/leon.hamm/bachelor-thesis-dev/novelty_tot/.venv/lib/python3.10/site-packages/httpx/_client.py\", line 1694, in _send_handling_redirects\n    response = await self._send_single_request(request)\n  File \"/work/rleap1/leon.hamm/bachelor-thesis-dev/novelty_tot/.venv/lib/python3.10/site-packages/httpx/_client.py\", line 1730, in _send_single_request\n    response = await transport.handle_async_request(request)\n  File \"/work/rleap1/leon.hamm/bachelor-thesis-dev/novelty_tot/.venv/lib/python3.10/site-packages/httpx/_transports/default.py\", line 393, in handle_async_request\n    with map_httpcore_exceptions():\n  File \"/usr/lib/python3.10/contextlib.py\", line 153, in __exit__\n    self.gen.throw(typ, value, traceback)\n  File \"/work/rleap1/leon.hamm/bachelor-thesis-dev/novelty_tot/.venv/lib/python3.10/site-packages/httpx/_transports/default.py\", line 118, in map_httpcore_exceptions\n    raise mapped_exc(message) from exc\nhttpx.ReadTimeout\n\nThe above exception was the direct cause of the following exception:\n\nTraceback (most recent call last):\n  File \"/work/rleap1/leon.hamm/bachelor-thesis-dev/novelty_tot/tot_tester.py\", line 504, in run_math_task_with_error_handling\n    answer = await tot.run(query, parallel=parallel, breadth_first=breadth_first, problem_width=problem_width)\n  File \"/work/rleap1/leon.hamm/bachelor-thesis-dev/novelty_tot/tot.py\", line 233, in run\n    await self._expand_depth_first(self.init_state, self.max_depth, parallel=parallel)\n  File \"/work/rleap1/leon.hamm/bachelor-thesis-dev/novelty_tot/tot.py\", line 305, in _expand_depth_first\n    await self._expand_node(state, depth=depth, parallel=parallel)\n  File \"/work/rleap1/leon.hamm/bachelor-thesis-dev/novelty_tot/tot.py\", line 279, in _expand_node\n    results = await asyncio.gather(*scheduled)\n  File \"/work/rleap1/leon.hamm/bachelor-thesis-dev/novelty_tot/tot.py\", line 265, in process_branch\n    succ = await self._generate_successor(node)\n  File \"/work/rleap1/leon.hamm/bachelor-thesis-dev/novelty_tot/tot.py\", line 426, in _generate_successor\n    response = await self.query(complete_prompt)\n  File \"/work/rleap1/leon.hamm/bachelor-thesis-dev/novelty_tot/tot.py\", line 193, in query\n    response = await self.llm_engine.query(query)\n  File \"/work/rleap1/leon.hamm/bachelor-thesis-dev/novelty_tot/llm_engine.py\", line 203, in query\n    response = await client.aquery(\n  File \"/work/rleap1/leon.hamm/bachelor-thesis-dev/novelty_tot/llm_engine.py\", line 88, in aquery\n    response = await self.chat.completions.create(\n  File \"/work/rleap1/leon.hamm/bachelor-thesis-dev/novelty_tot/.venv/lib/python3.10/site-packages/openai/resources/chat/completions/completions.py\", line 2454, in create\n    return await self._post(\n  File \"/work/rleap1/leon.hamm/bachelor-thesis-dev/novelty_tot/.venv/lib/python3.10/site-packages/openai/_base_client.py\", line 1791, in post\n    return await self.request(cast_to, opts, stream=stream, stream_cls=stream_cls)\n  File \"/work/rleap1/leon.hamm/bachelor-thesis-dev/novelty_tot/.venv/lib/python3.10/site-packages/openai/_base_client.py\", line 1544, in request\n    raise APITimeoutError(request=request) from err\nopenai.APITimeoutError: Request timed out.\n",
            "token_usage": 0,
            "num_times_pruned": 0
        },
        {
            "task_id": "43",
            "success": false,
            "answer": "Error occurred: APITimeoutError: Request timed out.\nTraceback:\nTraceback (most recent call last):\n  File \"/work/rleap1/leon.hamm/bachelor-thesis-dev/novelty_tot/.venv/lib/python3.10/site-packages/httpx/_transports/default.py\", line 101, in map_httpcore_exceptions\n    yield\n  File \"/work/rleap1/leon.hamm/bachelor-thesis-dev/novelty_tot/.venv/lib/python3.10/site-packages/httpx/_transports/default.py\", line 394, in handle_async_request\n    resp = await self._pool.handle_async_request(req)\n  File \"/work/rleap1/leon.hamm/bachelor-thesis-dev/novelty_tot/.venv/lib/python3.10/site-packages/httpcore/_async/connection_pool.py\", line 256, in handle_async_request\n    raise exc from None\n  File \"/work/rleap1/leon.hamm/bachelor-thesis-dev/novelty_tot/.venv/lib/python3.10/site-packages/httpcore/_async/connection_pool.py\", line 236, in handle_async_request\n    response = await connection.handle_async_request(\n  File \"/work/rleap1/leon.hamm/bachelor-thesis-dev/novelty_tot/.venv/lib/python3.10/site-packages/httpcore/_async/connection.py\", line 103, in handle_async_request\n    return await self._connection.handle_async_request(request)\n  File \"/work/rleap1/leon.hamm/bachelor-thesis-dev/novelty_tot/.venv/lib/python3.10/site-packages/httpcore/_async/http11.py\", line 136, in handle_async_request\n    raise exc\n  File \"/work/rleap1/leon.hamm/bachelor-thesis-dev/novelty_tot/.venv/lib/python3.10/site-packages/httpcore/_async/http11.py\", line 106, in handle_async_request\n    ) = await self._receive_response_headers(**kwargs)\n  File \"/work/rleap1/leon.hamm/bachelor-thesis-dev/novelty_tot/.venv/lib/python3.10/site-packages/httpcore/_async/http11.py\", line 177, in _receive_response_headers\n    event = await self._receive_event(timeout=timeout)\n  File \"/work/rleap1/leon.hamm/bachelor-thesis-dev/novelty_tot/.venv/lib/python3.10/site-packages/httpcore/_async/http11.py\", line 217, in _receive_event\n    data = await self._network_stream.read(\n  File \"/work/rleap1/leon.hamm/bachelor-thesis-dev/novelty_tot/.venv/lib/python3.10/site-packages/httpcore/_backends/anyio.py\", line 32, in read\n    with map_exceptions(exc_map):\n  File \"/usr/lib/python3.10/contextlib.py\", line 153, in __exit__\n    self.gen.throw(typ, value, traceback)\n  File \"/work/rleap1/leon.hamm/bachelor-thesis-dev/novelty_tot/.venv/lib/python3.10/site-packages/httpcore/_exceptions.py\", line 14, in map_exceptions\n    raise to_exc(exc) from exc\nhttpcore.ReadTimeout\n\nThe above exception was the direct cause of the following exception:\n\nTraceback (most recent call last):\n  File \"/work/rleap1/leon.hamm/bachelor-thesis-dev/novelty_tot/.venv/lib/python3.10/site-packages/openai/_base_client.py\", line 1526, in request\n    response = await self._client.send(\n  File \"/work/rleap1/leon.hamm/bachelor-thesis-dev/novelty_tot/.venv/lib/python3.10/site-packages/httpx/_client.py\", line 1629, in send\n    response = await self._send_handling_auth(\n  File \"/work/rleap1/leon.hamm/bachelor-thesis-dev/novelty_tot/.venv/lib/python3.10/site-packages/httpx/_client.py\", line 1657, in _send_handling_auth\n    response = await self._send_handling_redirects(\n  File \"/work/rleap1/leon.hamm/bachelor-thesis-dev/novelty_tot/.venv/lib/python3.10/site-packages/httpx/_client.py\", line 1694, in _send_handling_redirects\n    response = await self._send_single_request(request)\n  File \"/work/rleap1/leon.hamm/bachelor-thesis-dev/novelty_tot/.venv/lib/python3.10/site-packages/httpx/_client.py\", line 1730, in _send_single_request\n    response = await transport.handle_async_request(request)\n  File \"/work/rleap1/leon.hamm/bachelor-thesis-dev/novelty_tot/.venv/lib/python3.10/site-packages/httpx/_transports/default.py\", line 393, in handle_async_request\n    with map_httpcore_exceptions():\n  File \"/usr/lib/python3.10/contextlib.py\", line 153, in __exit__\n    self.gen.throw(typ, value, traceback)\n  File \"/work/rleap1/leon.hamm/bachelor-thesis-dev/novelty_tot/.venv/lib/python3.10/site-packages/httpx/_transports/default.py\", line 118, in map_httpcore_exceptions\n    raise mapped_exc(message) from exc\nhttpx.ReadTimeout\n\nThe above exception was the direct cause of the following exception:\n\nTraceback (most recent call last):\n  File \"/work/rleap1/leon.hamm/bachelor-thesis-dev/novelty_tot/tot_tester.py\", line 504, in run_math_task_with_error_handling\n    answer = await tot.run(query, parallel=parallel, breadth_first=breadth_first, problem_width=problem_width)\n  File \"/work/rleap1/leon.hamm/bachelor-thesis-dev/novelty_tot/tot.py\", line 233, in run\n    await self._expand_depth_first(self.init_state, self.max_depth, parallel=parallel)\n  File \"/work/rleap1/leon.hamm/bachelor-thesis-dev/novelty_tot/tot.py\", line 305, in _expand_depth_first\n    await self._expand_node(state, depth=depth, parallel=parallel)\n  File \"/work/rleap1/leon.hamm/bachelor-thesis-dev/novelty_tot/tot.py\", line 279, in _expand_node\n    results = await asyncio.gather(*scheduled)\n  File \"/work/rleap1/leon.hamm/bachelor-thesis-dev/novelty_tot/tot.py\", line 265, in process_branch\n    succ = await self._generate_successor(node)\n  File \"/work/rleap1/leon.hamm/bachelor-thesis-dev/novelty_tot/tot.py\", line 426, in _generate_successor\n    response = await self.query(complete_prompt)\n  File \"/work/rleap1/leon.hamm/bachelor-thesis-dev/novelty_tot/tot.py\", line 193, in query\n    response = await self.llm_engine.query(query)\n  File \"/work/rleap1/leon.hamm/bachelor-thesis-dev/novelty_tot/llm_engine.py\", line 203, in query\n    response = await client.aquery(\n  File \"/work/rleap1/leon.hamm/bachelor-thesis-dev/novelty_tot/llm_engine.py\", line 88, in aquery\n    response = await self.chat.completions.create(\n  File \"/work/rleap1/leon.hamm/bachelor-thesis-dev/novelty_tot/.venv/lib/python3.10/site-packages/openai/resources/chat/completions/completions.py\", line 2454, in create\n    return await self._post(\n  File \"/work/rleap1/leon.hamm/bachelor-thesis-dev/novelty_tot/.venv/lib/python3.10/site-packages/openai/_base_client.py\", line 1791, in post\n    return await self.request(cast_to, opts, stream=stream, stream_cls=stream_cls)\n  File \"/work/rleap1/leon.hamm/bachelor-thesis-dev/novelty_tot/.venv/lib/python3.10/site-packages/openai/_base_client.py\", line 1544, in request\n    raise APITimeoutError(request=request) from err\nopenai.APITimeoutError: Request timed out.\n",
            "token_usage": 0,
            "num_times_pruned": 0
        },
        {
            "task_id": "44",
            "success": true,
            "answer": "3",
            "token_usage": 4775,
            "num_times_pruned": 0
        },
        {
            "task_id": "45",
            "success": false,
            "answer": "Error occurred: APITimeoutError: Request timed out.\nTraceback:\nTraceback (most recent call last):\n  File \"/work/rleap1/leon.hamm/bachelor-thesis-dev/novelty_tot/.venv/lib/python3.10/site-packages/httpx/_transports/default.py\", line 101, in map_httpcore_exceptions\n    yield\n  File \"/work/rleap1/leon.hamm/bachelor-thesis-dev/novelty_tot/.venv/lib/python3.10/site-packages/httpx/_transports/default.py\", line 394, in handle_async_request\n    resp = await self._pool.handle_async_request(req)\n  File \"/work/rleap1/leon.hamm/bachelor-thesis-dev/novelty_tot/.venv/lib/python3.10/site-packages/httpcore/_async/connection_pool.py\", line 256, in handle_async_request\n    raise exc from None\n  File \"/work/rleap1/leon.hamm/bachelor-thesis-dev/novelty_tot/.venv/lib/python3.10/site-packages/httpcore/_async/connection_pool.py\", line 236, in handle_async_request\n    response = await connection.handle_async_request(\n  File \"/work/rleap1/leon.hamm/bachelor-thesis-dev/novelty_tot/.venv/lib/python3.10/site-packages/httpcore/_async/connection.py\", line 103, in handle_async_request\n    return await self._connection.handle_async_request(request)\n  File \"/work/rleap1/leon.hamm/bachelor-thesis-dev/novelty_tot/.venv/lib/python3.10/site-packages/httpcore/_async/http11.py\", line 136, in handle_async_request\n    raise exc\n  File \"/work/rleap1/leon.hamm/bachelor-thesis-dev/novelty_tot/.venv/lib/python3.10/site-packages/httpcore/_async/http11.py\", line 106, in handle_async_request\n    ) = await self._receive_response_headers(**kwargs)\n  File \"/work/rleap1/leon.hamm/bachelor-thesis-dev/novelty_tot/.venv/lib/python3.10/site-packages/httpcore/_async/http11.py\", line 177, in _receive_response_headers\n    event = await self._receive_event(timeout=timeout)\n  File \"/work/rleap1/leon.hamm/bachelor-thesis-dev/novelty_tot/.venv/lib/python3.10/site-packages/httpcore/_async/http11.py\", line 217, in _receive_event\n    data = await self._network_stream.read(\n  File \"/work/rleap1/leon.hamm/bachelor-thesis-dev/novelty_tot/.venv/lib/python3.10/site-packages/httpcore/_backends/anyio.py\", line 32, in read\n    with map_exceptions(exc_map):\n  File \"/usr/lib/python3.10/contextlib.py\", line 153, in __exit__\n    self.gen.throw(typ, value, traceback)\n  File \"/work/rleap1/leon.hamm/bachelor-thesis-dev/novelty_tot/.venv/lib/python3.10/site-packages/httpcore/_exceptions.py\", line 14, in map_exceptions\n    raise to_exc(exc) from exc\nhttpcore.ReadTimeout\n\nThe above exception was the direct cause of the following exception:\n\nTraceback (most recent call last):\n  File \"/work/rleap1/leon.hamm/bachelor-thesis-dev/novelty_tot/.venv/lib/python3.10/site-packages/openai/_base_client.py\", line 1526, in request\n    response = await self._client.send(\n  File \"/work/rleap1/leon.hamm/bachelor-thesis-dev/novelty_tot/.venv/lib/python3.10/site-packages/httpx/_client.py\", line 1629, in send\n    response = await self._send_handling_auth(\n  File \"/work/rleap1/leon.hamm/bachelor-thesis-dev/novelty_tot/.venv/lib/python3.10/site-packages/httpx/_client.py\", line 1657, in _send_handling_auth\n    response = await self._send_handling_redirects(\n  File \"/work/rleap1/leon.hamm/bachelor-thesis-dev/novelty_tot/.venv/lib/python3.10/site-packages/httpx/_client.py\", line 1694, in _send_handling_redirects\n    response = await self._send_single_request(request)\n  File \"/work/rleap1/leon.hamm/bachelor-thesis-dev/novelty_tot/.venv/lib/python3.10/site-packages/httpx/_client.py\", line 1730, in _send_single_request\n    response = await transport.handle_async_request(request)\n  File \"/work/rleap1/leon.hamm/bachelor-thesis-dev/novelty_tot/.venv/lib/python3.10/site-packages/httpx/_transports/default.py\", line 393, in handle_async_request\n    with map_httpcore_exceptions():\n  File \"/usr/lib/python3.10/contextlib.py\", line 153, in __exit__\n    self.gen.throw(typ, value, traceback)\n  File \"/work/rleap1/leon.hamm/bachelor-thesis-dev/novelty_tot/.venv/lib/python3.10/site-packages/httpx/_transports/default.py\", line 118, in map_httpcore_exceptions\n    raise mapped_exc(message) from exc\nhttpx.ReadTimeout\n\nThe above exception was the direct cause of the following exception:\n\nTraceback (most recent call last):\n  File \"/work/rleap1/leon.hamm/bachelor-thesis-dev/novelty_tot/tot_tester.py\", line 504, in run_math_task_with_error_handling\n    answer = await tot.run(query, parallel=parallel, breadth_first=breadth_first, problem_width=problem_width)\n  File \"/work/rleap1/leon.hamm/bachelor-thesis-dev/novelty_tot/tot.py\", line 233, in run\n    await self._expand_depth_first(self.init_state, self.max_depth, parallel=parallel)\n  File \"/work/rleap1/leon.hamm/bachelor-thesis-dev/novelty_tot/tot.py\", line 305, in _expand_depth_first\n    await self._expand_node(state, depth=depth, parallel=parallel)\n  File \"/work/rleap1/leon.hamm/bachelor-thesis-dev/novelty_tot/tot.py\", line 279, in _expand_node\n    results = await asyncio.gather(*scheduled)\n  File \"/work/rleap1/leon.hamm/bachelor-thesis-dev/novelty_tot/tot.py\", line 265, in process_branch\n    succ = await self._generate_successor(node)\n  File \"/work/rleap1/leon.hamm/bachelor-thesis-dev/novelty_tot/tot.py\", line 426, in _generate_successor\n    response = await self.query(complete_prompt)\n  File \"/work/rleap1/leon.hamm/bachelor-thesis-dev/novelty_tot/tot.py\", line 193, in query\n    response = await self.llm_engine.query(query)\n  File \"/work/rleap1/leon.hamm/bachelor-thesis-dev/novelty_tot/llm_engine.py\", line 203, in query\n    response = await client.aquery(\n  File \"/work/rleap1/leon.hamm/bachelor-thesis-dev/novelty_tot/llm_engine.py\", line 88, in aquery\n    response = await self.chat.completions.create(\n  File \"/work/rleap1/leon.hamm/bachelor-thesis-dev/novelty_tot/.venv/lib/python3.10/site-packages/openai/resources/chat/completions/completions.py\", line 2454, in create\n    return await self._post(\n  File \"/work/rleap1/leon.hamm/bachelor-thesis-dev/novelty_tot/.venv/lib/python3.10/site-packages/openai/_base_client.py\", line 1791, in post\n    return await self.request(cast_to, opts, stream=stream, stream_cls=stream_cls)\n  File \"/work/rleap1/leon.hamm/bachelor-thesis-dev/novelty_tot/.venv/lib/python3.10/site-packages/openai/_base_client.py\", line 1544, in request\n    raise APITimeoutError(request=request) from err\nopenai.APITimeoutError: Request timed out.\n",
            "token_usage": 0,
            "num_times_pruned": 0
        },
        {
            "task_id": "46",
            "success": true,
            "answer": "46",
            "token_usage": 3750,
            "num_times_pruned": 0
        },
        {
            "task_id": "47",
            "success": true,
            "answer": "5.29",
            "token_usage": 7011,
            "num_times_pruned": 0
        },
        {
            "task_id": "48",
            "success": true,
            "answer": "$$\n\\mathbf{R} = \\begin{pmatrix} \n\\frac{1}{3} & -\\frac{2}{3} & \\frac{2}{3} \\\\ \n-\\frac{2}{3} & \\frac{1}{3} & \\frac{2}{3} \\\\ \n\\frac{2}{3} & \\frac{2}{3} & \\frac{1}{3} \n\\end{pmatrix}\n$$",
            "token_usage": 8368,
            "num_times_pruned": 0
        },
        {
            "task_id": "49",
            "success": true,
            "answer": "The expected number of cards strictly between the two jokers is $ \\frac{52}{3} $.",
            "token_usage": 12423,
            "num_times_pruned": 0
        }
    ],
    "summary": {
        "total_tasks": 50,
        "successful_tasks": 38,
        "failed_tasks": 12,
        "total_token_usage": 439363,
        "total_num_times_pruned": 0,
        "num_early_stops": 0,
        "num_max_context_exceeded": 0,
        "num_max_retries_exceeded": 0,
        "num_retries": 2,
        "num_truncated_queries": 0,
        "num_shortened_prompts": 0
    },
    "duration": "0:41:09.639082"
}